Workbook

Sheet 2025-2026
A1: MATRIKS TENDER ON PROGRESS ZEUS
A2: Periode 2025-2026 | sheet: 2025-2026
K3: Status (Tanggal Milestone) | AA3: Pembuatan PO Screening Test
A4: No | B4: Area | C4: Coll. No. Tender | D4: Customer | E4: Product | F4: Entitas/Konsorsium | G4: Qty (Liter/Barel) | H4: OE (Rp) | I4: OE Catatan | J4: IDR/L | K4: Regist | L4: PQ | M4: Technical PQ | N4: Prebid | O4: Second Prebid | P4: Technical Bidding | Q4: Sampel Chemical diterima di Lab Test | R4: Pengiriman Bukti Pembayaran Lab Independent | S4: Pemasukan Dokumen Penawaran | T4: Field Test | U4: Open Bid | V4: First Delivery | W4: Result | X4: Carry-over | Y4: Remarks | Z4: Nilai Proyek Fix/Nilai Penawaran Kita | AA4: Remark | AB4: P&L | AC4: Checklist Document | AD4: Catatan Internal
A5: 1 | B5: Sumatera | D5: Petrochina International Jabung Ltd. | E5: Production Chemical Kompetisi di Petrochina Jabung | F5: ZKI | K5: 45359 | L5: 45365 | T5: 46054 | Y5: - Plant visit Jabek tanggal 4 Agustus 2025 - Field test tanggal 1 - 7 Februari 2026
A6: 2 | B6: Sumatera | C6: CS71965 | D6: PT Medco E & P Indonesia | E6: Chemical Treatment and Performance Observation Services for Produced Water and Gas Treatment in SSB and Lematang | F6: ZKI | K6: 45846 | L6: 45855 | N6: 46119 | Q6: 45904 | S6: 46135 | T6: 46064 | U6: 46135 | X6: Lanjutan dari 2024-2025 | Y6: - Field Test Deoiler (Jene Station) : 11 - 19 Februari 2026 - Field Test H2S Scavenger (Matra Station) : 20 - 28 Februari 2026
A7: 3 | B7: Jawa | C7: GX03051759A | D7: PT Pertamina Hulu Energi ONWJ | E7: Pengadaan Consignment Agreement for the Purchase of Chemical 2025 | F7: ZKI | H7: 176780466240 | K7: 45848 | L7: 45861 | N7: 46071 | Q7: 46155 | S7: 46154 | U7: 46154 | X7: Lanjutan dari 2024-2025 | Y7: - Lolos PQ
A8: 4 | B8: Sumatera | C8: CS72107 | D8: PT Medco E & P Rimau | E8: CHEMICAL TREATMENT AND PERFORMANCE OBSERVATION SERVICES FOR PRODUCED WATER RIMAU | F8: ZKI | K8: 45852 | L8: 45861 | Q8: 45915 | T8: 46034 | W8: WITHDRAW | X8: Lanjutan dari 2024-2025 | Y8: - Field Test : 12 - 20 Januari 2026 - Rapat Penjelasan PQ tahap 3 Tanggal 4 Juni 2026 Note: memutuskan tidak ikut field test ulang
A9: 5 | B9: Sumatera | C9: SA10050767C | D9: PT Pertamina EP | E9: JASA TREATMENT FLUIDA PRODUKSI DAN PENGINJEKSIAN CHEMICAL POUR POINT DEPRESSANT (PPD) DENGAN KONSEP TOTAL SOLUTION LIMAU FIELD | F9: ZKI | K9: 45868 | L9: 45910 | N9: 46122 | Q9: 45944 | R9: 45940 | S9: 46133 | T9: 46046 | U9: 46133 | W9: LOSS PRICE | X9: Lanjutan dari 2024-2025 | Y9: - Rapat penjelasan Lab Test 02 Oktober 2025 - Field Test : 24 - 28 Januari 2026 - Lulus Pembukaan Sampul 1 Ranking: 1. Farca Risa: 3,969,952,000 2. Eonchemicals: 4,641,655,000 3. Elnusa: 6,995,858,000 4. Zekindo: 7,875,318,000
A10: 6 | B10: Sumatera | C10: SRB-TDR-260-25 | D10: PT. SELE RAYA BELIDA | E10: Pengadaan Pour Point Depresant untuk mendukung operasional di Sumur Sungai Anggur Selatan-1, Wilayah Kerja Belida | F10: ZKI | K10: 45880 | L10: 45883 | X10: Lanjutan dari 2024-2025
A11: 7 | B11: Kalimantan | C11: SX14054033A | D11: PT Pertamina Hulu Mahakam | E11: Pengadaan Jasa Pengolahan South Area Production Liquid Treatment | F11: ZKI | K11: 45903 | L11: 45888 | Q11: 45981 | W11: LOSS TECHNICAL (BOTTLE TEST) | X11: Lanjutan dari 2024-2025 | Y11: Test performa Demulsifier tidak memenuhi kriteria
A12: 8 | B12: Papua | C12: 4420003900A | D12: BP Berau Ltd | E12: RENCANA PRAKUALIFIKASI UNTUK PENGADAAN JASA TEKNIS UJI KEBOCORAN DAN N2 PURGING FASILITAS PRODUKSI TANGGUH, SERTA PEMASOKAN DAN PENGELOLAAN BAHAN KIMIA | F12: ZKI - BEI | K12: 45929 | L12: 45943 | N12: 46114 | S12: 46150 | W12: WITHDRAW | X12: Lanjutan dari 2024-2025 | Y12: Tidak mendapatkan surat dukungan dari linde
A13: 9 | B13: Sumatera | C13: SX10053144C | D13: PT Pertamina EP | E13: JASA PENYEDIAAN DEMULSIFIER SECARA PERFORMANCE BASED DI PERTAMINA PENDOPO FIELD | F13: ZKI | K13: 45932 | L13: 45960 | Q13: 45986 | R13: 45982 | W13: WITHDRAW | X13: Lanjutan dari 2024-2025 | Y13: Memundurkan diri karena harga yang ditawarkan tidak bisa mengikuti OE yang sudah ditetapkan
A14: 10 | B14: Jawa | C14: GX13055420A | D14: PT Pertamina EP | E14: PENGADAAN CHEMICAL CORROSION INHIBITOR SECARA COO SELAMA 3 (TIGA) TAHUN DI PERTAMINA EP ZONA 7 | F14: ZKI | H14: 3400000000 | K14: 45933 | L14: 45954 | N14: 45996 | O14: 46006 | S14: 46021 | U14: 46021 | W14: LOSS TECHNICAL (BOTTLE TEST) | X14: Lanjutan dari 2024-2025 | Y14: Tidak Lulus Evaluasi Teknis
A15: 11 | B15: Kalimantan | C15: SX04055769 | D15: PT Pertamina Hulu Kalimantan Timur | E15: Penyediaan Jasa Bahan Kimia Produksi DOBS | F15: ZKI | K15: 45944 | L15: 45989 | Q15: 46072 | X15: Lanjutan dari 2024-2025 | Y15: - Lulus Lab Test
A16: 12 | B16: Sumatera | C16: SX10054381B | D16: PT Pertamina EP | E16: JASA TREATMENT PRODUCED WATER MENGGUNAKAN CHEMICAL SCALE INHIBITOR, CORROSION INHIBITOR, BIOCIDE, OXYGEN SCAVENGER DAN WATER CLARIFIER DENGAN KONSEP TOTAL SOLUTION BERIKUT JASA PENUNJANG DI ZONA 4 FIELD PRABUMULIH | F16: ZKI - RGA | K16: 45961 | L16: 46003 | Q16: 46049 | R16: 46044 | S16: 46094 | U16: 46094 | W16: LOSS PRICE | X16: Lanjutan dari 2024-2025
A17: 13 | B17: Jawa | C17: SX18057568A | D17: PT Pertamina EP Cepu | E17: Pengadaan Jasa Pengelolaan Bahan Kimia Pada Proses Pengolahan Air dan Gas di Zona 12 Regional 4 PT Pertamina EP Cepu | F17: ZKI | K17: 45989 | L17: 45995 | N17: 46036 | W17: LOSS TECHNICAL | X17: Lanjutan dari 2024-2025 | Y17: Dokumen tidak submit karena Dokumen technical belum lengkap
A18: 14 | B18: Jawa | C18: SX13057022A | D18: PT Pertamina EP | E18: JASA PENGGUNAAN DEMULSIFIER DI WILAYAH PT PERTAMINA EP ZONA 7 OGT | F18: ZKI | K18: 45995 | L18: 46000 | N18: 46041 | W18: WITHDRAW | X18: Lanjutan dari 2024-2025 | Y18: Memundurkan diri karena harga yang ditawarkan tidak bisa mengikuti OE yang sudah ditetapkan
A19: 15 | B19: Sumatera | C19: SX10055022B | D19: PT Pertamina EP | E19: JASA TREATMENT PRODUCED FLUID MENGGUNAKAN CHEMICAL DEMULSIFIER DENGAN KONSEP TOTAL SOLUTION BERIKUT JASA PENUNJANG DI PT. PERTAMINA EP ZONA 4 FIELD PRABUMULIH | F19: ZKI - RGA | K19: 45996 | L19: 46044 | N19: 46140 | Q19: 46090 | R19: 46084 | S19: 46153 | U19: 46153 | W19: LOSS PRICE | X19: Lanjutan dari 2024-2025 | Y19: -Sudah ditetapkan calon pemenang PT EONCHEMICALS PUTRA
A20: 16 | B20: Jawa | C20: GX13058666A | D20: PT Pertamina EP | E20: PENGADAAN SCALE INHIBITOR SECARA CALL OF ORDER (COO) SELAMA 3 TAHUN DI PT PERTAMINA EP ZONA 7 | F20: ZKI | H20: 5250000000 | K20: 46014 | L20: 46035 | N20: 46084 | Q20: 46122 | R20: 46126 | S20: 46112 | U20: 46112 | W20: CANCELED | X20: Lanjutan dari 2024-2025 | Y20: - Tender BATAL karena Maksimal 60 (enam puluh) hari kerja untuk pelelangan barang.
A21: 17 | B21: Jawa | C21: SX12069030A | D21: PT Pertamina Hulu Energi OSES | E21: Pengadaan Jasa Chemical Supply and Service for Gas Operation | F21: ZKI | H21: 47514313751 | K21: 46020 | L21: 46045 | N21: 46091 | S21: 46146 | U21: 46146 | W21: LOSS PRICE | X21: Lanjutan dari 2024-2025 | Y21: - 19 Mei 2026 site visit ke Jababeka Ranking : 1. CATUR INTI CHEMICAL : 32,067,816,660 2. LAMURINDO : 39,981,815,775 3. ZEKINDO : 40,668,658,571 4 4. LBU: 42,921,945,000 5. ELNUSA PETROFIN: 53,872,371,861
A22: 18 | B22: Kalimantan | C22: GX14059143A | D22: PT Pertamina Hulu Mahakam | E22: Pengadaan Bahan Kimia Reverse Demulsifier CPA | F22: ZKI | K22: 46031 | L22: 46051 | Q22: 46118 | W22: LOSS TECHNICAL | Y22: Tidak memenuhi Persyaratan Teknis yang tertera pada Dokumen Prakualifikasi (Tahap II) pada Teknis Khusus ketentuan II.B, butir 5 yaitu: Test Performa (Uji Laboratorium) & HSSE terhadap MSDS: 1. oil content > 10 ppm 2. Nilai Efektifitas < 90%. 3. Data Toksikologi LC 50 tidak tersedia
A23: 19 | B23: Jawa | C23: GX17059342A | D23: PT Pertamina EP | E23: Pengadaan Chelating Agent Untuk Sulfur Recovery Unit (SRU) di PT Pertamina EP Sukowati Field | F23: ZKI | K23: 46042 | Q23: 46052 | W23: LOSS TECHNICAL (BOTTLE TEST) | Y23: - Submit sample ke LAPI ITB : 30 Januari 2026 Dinyatakan Tidak Lulus Prakualifikasi Tahap Uji Laboratorium dikarenakan : 1. Pada Parameter Compatibilty with existing chelating Larutan tidak tercampur sempurna, keruh dan ada endapan 2. Pada Klarifikasi Prakualifikasi hasil Uji laboratorium dengan tanggal 6 April 2026, PT Zeus Kimiatama Indonesia memahami, menyetujui dan menerima penjelasan atas hasil laboratorium yang sudah disampaikan
A24: 20 | B24: Jawa | C24: 192-OPS-PEB-III-2026 | D24: PT. Prima Energi Bawean | E24: Kebutuhan Demulsifier dan Wax Inhibitor | F24: ZKI | Q24: 46065 | U24: 46204 | W24: CANCELED
A25: 21 | B25: Kalimantan | C25: GX16000040A | D25: PT Pertamina EP | E25: Gas Corrosion Inhibitor untuk Lapangan Bunyu | F25: ZKI | K25: 46044 | L25: 46058 | N25: 46190 | W25: LOSS PRICE | Y25: Peringkat 3 1. Lamurindo : Rp 211,183,750.00 2. Elunusa Petrofin : 263,890,000.00 3. ZEKINDO : 307,998,950.00 4. Mitrabina Rekaniaga : 296,803,500.00 5. Rakhara Chemical : 375,000,000.00
A26: 22 | B26: Kalimantan | C26: GX04059917A | D26: PT Pertamina Hulu Sanga Sanga | E26: Konsinyasi Oil Treating PHSS | F26: ZKI | K26: 46059 | L26: 46090 | Q26: 46177
A27: 23 | B27: Sumatera | C27: D263/OM#1425 | D27: Petrochina International Jabung Ltd. | E27: Scale Inhibitor | F27: ZKI | K27: 46059
A28: 24 | B28: Sumatera | C28: GPHR00756A | D28: PT Pertamina Hulu Rokan | E28: Pengadaan Chemical Coagulant & Flocculant | F28: ZKI | K28: 46126 | N28: 46136 | S28: 46227 | U28: 46227 | W28: LOSS TECHNICAL (BOTTLE TEST)
A29: 25 | B29: Sumatera | C29: CS79359 | D29: Medco E & P Rimau | E29: Provision of Chemical Treatment and Performance Monitoring Services for Gas Rimau | F29: ZKI | K29: 46064 | L29: 46073 | M29: 46125 | Q29: 46125 | W29: WITHDRAW | Y29: - 18 Mei 2026 : Meeting FT
A30: 26 | B30: Sumatera | C30: CM80275 | D30: Medco E & P Indonesia | E30: CALL OFF ORDER POUR POINT DEPRESSANT (PPD), DEMULSIFIER AND SCALE INHIBITOR FOR META, LICA AND MATRA | F30: ZKI | K30: 46085 | L30: 46094 | Q30: 46167 | W30: LOSS TECHNICAL (BOTTLE TEST) | Y30: - 29 April 2026. pukul 14.00 WIB : Meeting Tahap 2 (Lab Test) Note: 1 (satu) dari 5 (lima) pengujian tidak memenuhi kriteria kelulusan yang telah ditetapkan.
A31: 27 | B31: Sumatera | C31: D263 / RO#1425 / QR#2393 | D31: Petrochina International Jabung Ltd. | E31: SCALE INHIBITOR (WATER TREATMENT) | F31: ZKI | S31: 46155 | Y31: - Openbid dilakukan oleh internal Petrochina
A32: 28 | B32: Sumatera | C32: D263 / RO#1535 / QR#2456 | D32: Petrochina International Jabung Ltd. | E32: PARAFIN SOLVENT | F32: ZKI | S32: 46198 | W32: WITHDRAW | Y32: Memundurkan diri karena harga yang ditawarkan tidak bisa mengikuti OE yang sudah ditetapkan
A33: 29 | B33: Jawa | C33: 001/MGAUE/VI/2026 | D33: PT. MGA Utama Energi | E33: Pekerjaan Chemical Injection Crude Oil Sepanjang & Pagerungan | F33: ZKI | K33: 46204
A34: 30 | B34: Jawa | C34: GX13063661A | D34: PT Pertamina EP | E34: PENGADAAN SCALE INHIBITOR SECARA CALL OF ORDER (COO) SELAMA 3 TAHUN DI PT PERTAMINA EP ZONA 7 | F34: ZKI | K34: 46199 | L34: 46225
A35: 31 | B35: Jawa | C35: GX13063750A | D35: PT Pertamina EP | E35: Pengadaan Chemical Corrosion Inhibitor for Wet Gas secara Call off Order (COO) selama 2 Tahun untuk Memenuhi Kebutuhan Operasional di PT Pertamina EP Zona 7 | F35: ZKI | K35: 46203 | L35: 46211
A36: 32 | B36: Sumatera | C36: COM-2605006 | D36: Texcal Energy Mahato Inc. | E36: Provision of Blanket Chemicals Supply & Services | F36: ZKI | K36: 46199 | W36: LOSS REGIST | Y36: SPDA yang Perusahaan termasuk golongan usaha “Besar” sedangkan yang diminta Golongan usaha menengah
A37: 33 | B37: Jawa | C37: 192-OPS-PEB-III-2026 R1 | D37: PT. Prima Energi Bawean | E37: Provision Chemical Demulsifier and Wax Inhibitor for CW-2 R1 | F37: ZKI | H37: 424695600 | N37: 46208 | S37: 46212 | U37: 46212 | W37: LOSS PRICE
A38: 34 | B38: Sumatera | C38: D263/OM#1581/QR#2540 | D38: Petrochina International Jabung Ltd. | E38: CHEMICAL H2S SCAVENGER | F38: ZKI | H38: 176000000 | S38: 46225 | U38: 46225
A39: 35 | B39: Sumatera | C39: BOSL-B26-008 | D39: Bass Oil Sukananti Limited | E39: Pengadaan Chemicals Demulsifier (DM), Pour Point Dispersant (PPD) dan Scale Inhibitor (SI) untuk selama 12 Bulan | F39: ZKI | K39: 46226 | L39: 46227
A40: 36 | B40: Sumatera | C40: GX07000053A | D40: PT Pertamina EP | E40: Pengadaan Chemical Stimulasi Sumuran Lirik Field Secara Call of Order (COO) Selama 3 (tiga) Tahun | F40: ZKI | K40: 46240
...

Sheet 2024-2025
A1: MATRIKS TENDER ON PROGRESS ZEUS
A2: Periode 2024-2025 | sheet: 2024-2025
K3: Status (Tanggal Milestone) | AA3: Pembuatan PO Screening Test
A4: No | B4: Area | C4: Coll. No. Tender | D4: Customer | E4: Product | F4: Entitas/Konsorsium | G4: Qty (Liter/Barel) | H4: OE (Rp) | I4: OE Catatan | J4: IDR/L | K4: Regist | L4: PQ | M4: Technical PQ | N4: Prebid | O4: Second Prebid | P4: Technical Bidding | Q4: Sampel Chemical diterima di Lab Test | R4: Pengiriman Bukti Pembayaran Lab Independent | S4: Pemasukan Dokumen Penawaran | T4: Field Test | U4: Open Bid | V4: First Delivery | W4: Result | X4: Carry-over | Y4: Remarks | Z4: Nilai Proyek Fix/Nilai Penawaran Kita | AA4: Remark | AB4: P&L | AC4: Checklist Document | AD4: Catatan Internal
A5: 1 | C5: SA17023583A | D5: PT Pertamina Hulu Energi WMO | E5: Integrated Chemical | F5: ZKI | I5: Dirahasiakan | K5: 45124 | L5: 45163 | M5: 45190 | N5: 45336 | Q5: 45231 | S5: 45351 | T5: 45281 | U5: 45351 | W5: WIN | X5: Lanjutan dari 2023-2024 | Y5: - Sudah proses lab test di Sucofindo, sudah selesai & lolos FT (pengumuman resmi dari panitia). - Telah dilakukan pembukaan sampul 1 dan menunggu informasi/undangan selanjutnya terkait pembukaan sampul 2 - Lolos evaluasi administrasi dan teknis (sampul 1), next pembukaan sampul 2 | AA5: ada totetank, menunggu field trial, head to head dengan LBU (totetank daily 4 pcs saja sisanya mau dinego dengan ibc plastik, basket butuh 22); douglas basket 3 pallet, paralel cek ke yang laing; MEA : invite meeting minggu depan; cari harga triazine impor sendiri, source lain di lokal, MEA & paraform dari luar | AB5: =FALSE() -> FALSE | AC5: =FALSE() -> FALSE
A6: 2 | C6: GA14024755A | D6: PT Pertamina Hulu Mahakam | E6: Demulsifier Lapangan CPA | F6: ZKI | H6: 28237001760 | K6: 45149 | L6: 45163 | M6: 45190 | Q6: 45204 | S6: 45383 | U6: 45383 | W6: LOSS PRICE | X6: Lanjutan dari 2023-2024 | Y6: Sudah proses open-bid (PT Zeus peringkat 4) | AA6: surfaktan petrogresik | AB6: =FALSE() -> FALSE | AC6: =FALSE() -> FALSE | AD6: follow up pendaftaran vendor
A7: 3 | C7: GA14025375A | D7: PHM | E7: Biocide Glutaraldehyde | F7: ZKI | H7: 44580848000 | K7: 45173 | L7: 45187 | M7: 45204 | Q7: 45251 | S7: 45385 | U7: 45385 | W7: LOSS PRICE | X7: Lanjutan dari 2023-2024 | Y7: - submit sample - telah dilakukan pembukaan dokumen penawaran | AB7: =FALSE() -> FALSE | AC7: =FALSE() -> FALSE | AD7: 23.12.27 : sudah minta target price
A8: 4 | C8: GA17024763A | D8: PEP Cepu | E8: Demulsifier | F8: ZKI | K8: 45176 | L8: 45209 | N8: 45289 | S8: 45299 | W8: WITHDRAW | X8: Lanjutan dari 2023-2024 | AB8: =FALSE() -> FALSE | AC8: =FALSE() -> FALSE | AD8: V:\SOURCING ZEKINDO\@ 000_TENDER\21. 23.12_Tender O&G_PEP Cepu
A9: 5 | C9: SA14025585A | D9: PHM | E9: North Area Production Liquid Treatment Service Contract | F9: ZKI | H9: 40800000000 | K9: 45184 | L9: 45211 | M9: 45236 | Q9: 45288 | S9: 45506 | U9: 45506 | W9: LOSS PRICE | X9: Lanjutan dari 2023-2024 | Y9: - pengambilan sampel liquid 17-20 Nov, bawa 6 tincan, sudah submit sample - Resampling PQ Teknis : Pengambilan sample di Handil II Base : 10 Maret 2024 Submit sample di Jakarta : 27 Maret 2024 - Telah dilakukan open-bid sampul 1 (Admin dan Teknis) | AB9: =FALSE() -> FALSE | AC9: =FALSE() -> FALSE | AD9: 23.12.28 belum ada formula dari R&D
A10: 6 | C10: SHUH-230631A-A10 | D10: PEP Zona 4 - Ramba | E10: Demulsifier & Deoiler | F10: ZKI | H10: 4952260000 | K10: 45216 | L10: 45216 | M10: 45244 | N10: 45236 | Q10: 45264 | R10: 45264 | S10: 45244 | U10: 45244 | W10: LOSS TECHNICAL | X10: Lanjutan dari 2023-2024 | Y10: sampul 1 terlebih dahulu, pengambilan crude water 14/11, tahap klarifikasi/sanggahan atas hasil lab test | AB10: =FALSE() -> FALSE | AC10: =TRUE() -> TRUE | AD10: LOST?
A11: 7 | C11: SHUH-230634A-A10 | D11: PEP Zona 4 - Limau | E11: PPD | F11: ZKI | G11: 76000 | H11: 4940000000 | J11: 65000 | K11: 45216 | L11: 45216 | M11: 45233 | N11: 45233 | Q11: 45278 | R11: 45274 | S11: 45253 | U11: 45253 | W11: LOSS PRICE | X11: Lanjutan dari 2023-2024 | Y11: sampul 1 terlebih dahulu, pengambilan crude 6-8/11, pengujian sample di LEMIGAS, est. hasil mid januari, Lab test Lolos. Harga penawaran ranking 2 | AA11: submitted | AB11: =TRUE() -> TRUE | AC11: =TRUE() -> TRUE | AD11: SUBMIT
A12: 8 | C12: 23110515-OR (Re-Tender) | D12: Premier Oil Natuna Sea B.V. | E12: Provision of Chemical Supply and Services | F12: ZKI | I12: $ 966.188 (USD) | K12: 45251 | N12: 45252 | O12: 45268 | S12: 45301 | U12: 45302 | W12: LOSS TECHNICAL | X12: Lanjutan dari 2023-2024 | Y12: Sample chemical sudah ready, sudah submit sample dan dokumen penawaran, 26 januari 2024 technical clarification meeting | AA12: jadwal bid mundur | AB12: =TRUE() -> TRUE | AC12: =TRUE() -> TRUE | AD12: NOTIFY
A13: 9 | C13: NDS-10115464 | D13: ENI MUARA BAKAU B.V. | E13: Provision of Fluid Speciality Chemical Treatment Services | F13: ZKI | K13: 45252 | L13: 45261 | N13: 45357 | W13: WITHDRAW | X13: Lanjutan dari 2023-2024 | AB13: =FALSE() -> FALSE | AC13: =FALSE() -> FALSE
A14: 10 | C14: GA07028191A | D14: PHE Jambi Merang | E14: Purchase of Specialty Chemicals | F14: ZKI | I14: Dirahasiakan | N14: 45273 | O14: 45299 | S14: 45334 | U14: 45334 | W14: WIN | X14: Lanjutan dari 2023-2024 | Y14: - Jadwal pemasukan dokumen penawaran akan diinfo pada Pre-bid ke-2 stlh menunggu sample diterima oleh bidder - Lab Independen menggunakan LAPI ITB, tanggal submission sample menunggu sample water dr PHE JM diterima di KBI - Tahap Negosiasi Harga - Menang | AA14: jadwal bid mundur, sampel belum dapat | AB14: =FALSE() -> FALSE | AC14: =TRUE() -> TRUE
A15: 11 | C15: SA04027442A | D15: Pertamina Hulu Kalimantan Timur (PHKT) | E15: Penyediaan Jasa Bahan Kimia Produksi DOBU-DOBS | F15: ZKI | I15: Dirahasiakan | N15: 45279 | S15: 45358 | U15: 45358 | W15: WIN | X15: Lanjutan dari 2023-2024 | Y15: - Submit sample ke Lemigas : 7 Maret 2024 Submit sample ke PHKT : 19 Maret 2024 - Pembukaan Sampul 1 DOBS dan DOBU - Pembukaan sampul 2 DOBU | AB15: =FALSE() -> FALSE | AC15: =TRUE() -> TRUE | AD15: NOTIFY
A16: 12 | C16: 29856 | D16: Pertamina Gas | E16: Kontrak Payung Jasa Operasional dan Pemeliharaan Pekerjaan Injeksi Pour Point Depresant | F16: ZKI | N16: 45288 | S16: 45322 | U16: 45322 | W16: WITHDRAW | X16: Lanjutan dari 2023-2024 | Y16: Tanggal 8 - 9 Januari 2024 pengambilan sample di Area Rokan
A17: 13 | C17: SA15031136A | D17: PT Pertamina EP Zona 9 (Sanga-Sanga) | E17: Jasa Penyediaan Chemical, Demulsifier & Deoiler C/W Engineer dan PPD | F17: ZKI | H17: 11165527440 | K17: 45307 | L17: 45310 | N17: 45370 | O17: 45386 | Q17: 45398 | W17: LOSS TECHNICAL (FIELD TRIAL) | X17: Lanjutan dari 2023-2024 | Y17: - Tanggal 16 April 2024 pengambilan sample dan masing-masing bidder membawa 2 wadah dengan penyediaan sample pertitik adalah 45 liter. - Tanggal 29 Mei 2024 meeting koordinasi Field Test
A18: 14 | C18: 1/DPM/12/2023 | D18: PT Pertamina Hulu Rokan | E18: Jasa Penyediaan Polimer dan Fasilitas Injeksi Polimer untuk CEOR Minas Area-D Tahap-1 | F18: ZKI - NUOER | K18: 45310 | L18: 45323 | W18: LOSS TECHNICAL | X18: Lanjutan dari 2023-2024
A19: 15 | C19: SHUH-240028A-A10 | D19: PT Pertamina EP Zona 4 | E19: Pengadaan Bahan Kimia dan Jasa Service Demulsifier dan Water Clarifier di Pertamina Zona 4 Field Ramba | F19: ZKI | K19: 45337 | L19: 45337 | N19: 45356 | W19: WITHDRAW | X19: Lanjutan dari 2023-2024
A20: 16 | C20: 1/DPM/3/2024 | D20: Pertamina Hulu Rokan (PHR) | E20: Jasa-Jasa Penyediaan Polimer, Reaktivasi dan Peningkatan Kapasitias Fasilitas On-plot untuk Proyek Pengembangan Minas CEOR Stage-1 | F20: ZKI - NUOER | K20: 45379 | L20: 45386 | Q20: 45405 | W20: LOSS TECHNICAL | X20: Lanjutan dari 2023-2024
A21: 17 | C21: SA10033496A | D21: PT Pertamina EP | E21: Jasa Service Treatment Fluida Produksi & Penginjeksian Chemical Demulsifier Dengan Konsep Total Solutih di PT PERTAMINA EP Limau Field Selama 3 (Tiga) Tahun | F21: ZKI | K21: 45369 | L21: 45415 | W21: LOSS PQ ADMIN | X21: Lanjutan dari 2023-2024
A22: 18 | C22: GA04029857A | D22: PT Pertamina Hulu Mahakam | E22: Pengadaan Bersama Kontrak COO General Chemical Regional 3 | F22: ZKI | K22: 45400 | L22: 45442 | W22: WITHDRAW | X22: Lanjutan dari 2023-2024
A23: 19 | C23: GA14033525A | D23: PT Pertamina Hulu Mahakam | E23: Pengadaan PWT (Potable Water Treatment) untuk 1 (satu) tahun kontrak COO (Call Off Order) | F23: ZKI | K23: 45427 | L23: 45442 | W23: LOSS PQ ADMIN | X23: Lanjutan dari 2023-2024
A24: 20 | C24: GA04029787A | D24: PT Pertamina Hulu Mahakam | E24: Pengadaan Bersama Kontrak COO Chemical Water Treatment Regional 3 | F24: ZKI | K24: 45506 | S24: 45603 | U24: 45603 | W24: LOSS PRICE | X24: Lanjutan dari 2023-2024
A25: 21 | C25: D263/RO#724/QR#1055 | D25: Petrochina International Jabung Ltd. | E25: Parafin Solvent | F25: ZKI | G25: 11000 | H25: 291500000 | S25: 45450 | U25: 45450 | W25: WIN | X25: Lanjutan dari 2023-2024
A26: 22 | C26: GA17036317A | D26: PT Pertamina EP | E26: Pengadaan Chemical Demulsifier untuk Operasional PT Pertamina EP Cepu Field | F26: ZKI | K26: 45447 | W26: NO INFO | X26: Lanjutan dari 2023-2024 | Y26: Hingga saat ini tidak ada kepastian kelanjutan
A27: 23 | C27: GA17032921A | D27: PT Pertamina EP | E27: PENGADAAN BAHAN KIMIA H2S SCAVENGER DI PT PERTAMINA EP SUKOWATI FIELD SECARA CALL OF ORDER (COO) | F27: ZKI | H27: 4836000000 | K27: 45357 | N27: 45405 | Q27: 45443 | S27: 45492 | U27: 45492 | W27: WIN | X27: Lanjutan dari 2023-2024 | Y27: Telah dilakukan openbid, menunggu pengumuman resmi surat penunjukan pemenang
A28: 24 | C28: 13089 | D28: Petronas (PC Ketapang II Ltd.) | E28: PROVISION OF INTEGRATED CHEMICALS SUPPLY & TECHNICAL SUPPORT SERVICES | F28: ZKI | L28: 45467 | Q28: 45632 | S28: 45632 | U28: 45751 | W28: WIN | X28: Lanjutan dari 2023-2024 | Y28: - Telah dilakukan openbid sampul 1 - Dilakukan site visit ke pabrik jababeka pada tanggal 13 Desember 2024 sebagai evaluasi teknis - Tahap klarifikasi komersial setelah open bid sampul 2
A29: 25 | C29: M/0358/15417/EEES | D29: Energy Equity Epic (Sengkang) Pty. Ltd. | E29: Supply of Corrosion Inhibitor | F29: ZKI | S29: 45498 | U29: 45498 | W29: LOSS PRICE | X29: Lanjutan dari 2023-2024 | Y29: Open-bid dilakukan oleh internal perusahaan
A30: 26 | D30: Petrochina International Jabung Ltd. | E30: Production Chemical Kompetisi di Petrochina Jabung | F30: ZKI | K30: 45359 | L30: 45365 | Y30: - Plant visit Jabek tanggal 4 Agustus 2025
A31: 27 | C31: SA17037613A | D31: PT Pertamina EP | E31: JASA TREATMENT SCALE DI SUMUR DAN FASILITAS PRODUKSI DENGAN CHEMICAL SCALE DAN CORROSION INHIBITOR | F31: ZKI | K31: 45490 | L31: 45513 | Q31: 45621 | S31: 45646 | U31: 45646 | W31: LOSS TECHNICAL | X31: Lanjutan dari 2023-2024 | Y31: Lolos Lab Test
A32: 28 | C32: SA10039381A | D32: PT Pertamina EP | E32: JASA TREATMENT PRODUCED FLUID, PRODUCED WATER DAN GAS MENGGUNAKAN CHEMICALS SCALE INHIBITOR, CORROSION INHIBITOR, BIOCIDE DAN H2S SCAVENGER DENGAN KONSEP TOTAL SOLUTION BERIKUT JASA PENUNJANG SELAMA 36 BULAN KALENDER DI PT. PERTAMINA EP LIMAU FIELD | F32: ZKI | I32: Dirahasiakan | K32: 45523 | L32: 45560 | N32: 45608 | Q32: 45621 | R32: 45618 | S32: 45652 | U32: 45652 | W32: LOSS TECHNICAL | X32: Lanjutan dari 2023-2024 | Y32: Loss HSE Plan (nilai di bawah 50%)
A33: 29 | C33: 044124 | D33: PT Pertamina Gas | E33: Kontrak Payung Jasa Operasional dan Pemeliharaan Pekerjaan Injeksi Pour Point Depresant Rokan Area | F33: ZKI | I33: Dirahasiakan | S33: 45649 | W33: WITHDRAW | X33: Lanjutan dari 2023-2024
A34: 30 | C34: GA03044628A | D34: PT Pertamina Hulu Energi ONWJ | E34: Consignment Agreement for the Purchase of Chemical | F34: ZKI | I34: Dirahasiakan | N34: 45630 | W34: CANCELED | X34: Lanjutan dari 2023-2024 | Y34: - Submit Form RFI dan Summary Bid Data Sheet - Pemasukan Dokumen Penawaran diundur hingga waktu yang tidak dapat ditentukan oleh panitia
A35: 31 | C35: CM59697-1 | D35: Medco E&P Natuna Ltd. | E35: CALL OFF ORDER TRI ETHYLENE GLYCOL (TEG) | F35: ZKI | K35: 45604 | L35: 45618 | N35: 45653 | Q35: 45678 | S35: 45688 | U35: 45688 | W35: LOSS TECHNICAL | X35: Lanjutan dari 2023-2024 | Y35: Klarifikasi Teknis 12 Feb 2025
A36: 32 | C36: GA04025007A | D36: PT Pertamina Hulu Sanga Sanga | E36: Konsinyasi Oil Treating PHSS | F36: ZKI | I36: Dirahasiakan | N36: 45638 | Q36: 45744 | S36: 45768 | U36: 45768 | W36: LOSS TECHNICAL | X36: Lanjutan dari 2023-2024 | Y36: Pengambilan sample crude 11 Februari 2025
A37: 33 | C37: GA14045476A | D37: PT Pertamina Hulu Mahakam | E37: PENGADAAN CORROSION INHIBITOR UNTUK 3 (TIGA) TAHUN DENGAN SKEMA KONTRAK CALL-OFF ORDER | F37: ZKI | H37: 48182800000 | K37: 45644 | L37: 45666 | M37: 45694 | S37: 45798 | U37: 45798 | W37: WIN | Y37: Tahap pemasukan sample chemical | Z37: 30644000000
A38: 34 | C38: D263/OM#874/QR#1398 | D38: Petrochina International Jabung Ltd. | E38: Oxygen Scavenger | F38: ZKI | G38: 2400 | H38: 129600000 | S38: 45688
A39: 35 | C39: D263/OM#943/QR#1433 | D39: Petrochina International Jabung Ltd. | E39: Microbiocide | F39: ZKI | G39: 8400 | H39: 344400000 | S39: 45714 | U39: 45714 | W39: LOSS PRICE
A40: 36 | C40: 4420003900 | D40: BP Berau Ltd. | E40: JASA TEKNIS UJI KEBOCORAN & N2 PURGING FASILITAS PRODUKSI TANGGUH, SERTA PEMASOKAN DAN PENGELOLAAN BAHAN KIMIA/TANGGUH PRODUCTION FACILITY LEAK TEST & N2 PURGING, AND CHEMICAL SUPPLIES AND MANAGEMENT SERVICES | F40: ZKI - TRC | K40: 45712 | L40: 45758 | W40: CANCELED | Y40: - Konsorsium dengan Tracon (Tracon bagian Leak Test and LN2 Purge. Zeus bagian Chemicals Supplies and Management Service)
...

Sheet 2023-2024
A1: MATRIKS TENDER ON PROGRESS ZEUS
A2: Periode 2023-2024 | sheet: 2023-2024
K3: Status (Tanggal Milestone) | AA3: Pembuatan PO Screening Test
A4: No | B4: Area | C4: Coll. No. Tender | D4: Customer | E4: Product | F4: Entitas/Konsorsium | G4: Qty (Liter/Barel) | H4: OE (Rp) | I4: OE Catatan | J4: IDR/L | K4: Regist | L4: PQ | M4: Technical PQ | N4: Prebid | O4: Second Prebid | P4: Technical Bidding | Q4: Sampel Chemical diterima di Lab Test | R4: Pengiriman Bukti Pembayaran Lab Independent | S4: Pemasukan Dokumen Penawaran | T4: Field Test | U4: Open Bid | V4: First Delivery | W4: Result | X4: Carry-over | Y4: Remarks | Z4: Nilai Proyek Fix/Nilai Penawaran Kita | AA4: Remark | AB4: P&L | AC4: Checklist Document | AD4: Catatan Internal
A5: 1 | C5: EPPC-221355A-P23 | D5: PEP Zona 9 - Sangasanga | E5: PPD | F5: ZKI | G5: 7000 | H5: 332500000 | J5: 47500 | K5: 44894 | L5: 44894 | M5: - | N5: - | Q5: - | R5: - | S5: 44929 | T5: - | U5: 44929 | W5: WIN | Y5: penunjukkan pemenang | Z5: 307300000
A6: 2 | C6: M23PL0028A | D6: Pertamina Drilling Services Indonesia | E6: LTC Chemical Aerated | F6: ZKI | H6: 300000000 | K6: 45056 | N6: 45057 | U6: 45065 | W6: WIN | Z6: 295440
A7: 3 | C7: SA14022436A | D7: PHM | E7: NPU-SNB Liquid Treatment Services (Demulsifier & Deoiler) | F7: ZKI | H7: 7268720000 | K7: 45109 | L7: 45111 | U7: 45125 | V7: 45200 | W7: WIN | Z7: 7113112000
A8: 4 | C8: GZ0700063A | D8: PEP Zona 7 - Jatibarang | E8: H2S Scavenger | F8: ZKI | G8: 70000 | H8: 3325000000 | J8: 47500 | K8: 44956 | L8: 44985 | M8: 45013 | N8: 45093 | Q8: 45026 | R8: 45026 | S8: 45100 | U8: 45100 | W8: LOSS PRICE | Y8: kalah harga dari DKJ | Z8: 2894981250
A9: 5 | C9: SA17018380A | D9: PEP - Sukowati | E9: KOH 45% | F9: ZKI | G9: 223000 | H9: 9366000000 | J9: 42000 | K9: 44958 | L9: 45034 | N9: 45083 | Q9: 45065 | S9: 45090 | U9: 45096 | W9: LOSS PRICE | Y9: kalah harga dari C3, kesalahan surat penawaran | Z9: 4192400000
A10: 6 | C10: GA03022207A | D10: PEP Zona 7 - Jatibarang | E10: PPD | F10: ZKI | G10: 687000 | H10: 31602000000 | J10: 46000 | K10: 45093 | L10: 45114 | M10: 45120 | N10: 45175 | Q10: 45133 | R10: 45132 | S10: 45183 | U10: 45183 | W10: LOSS PRICE | Y10: kalah harga dari Beta Pramesti, kekurangan dokumen dalam MOM Prebid
A11: 7 | C11: EPZ1-S22PL0007B-CP4 | D11: PEPC - Jambaran Tiung Biru | E11: Integrated Chemical | F11: ZKI | H11: 36825552304 | K11: - | L11: - | M11: - | N11: 44973 | Q11: - | R11: - | S11: 44985 | W11: LOSS TECHNICAL | Y11: kesalahan pada CoA Sodium Bisulfite | Z11: 33007037758
A12: 8 | C12: GA16017973A | D12: PEP Zona 10 - Tarakan | E12: Demulsifier, Deoiler | F12: ZKI | K12: 44945 | L12: 44963 | M12: 44971 | N12: 44959 | Q12: 44999 | R12: - | W12: LOSS TECHNICAL | Y12: tidak lolos lab test
A13: 9 | C13: BID 22-0105 | D13: Saka Indonesia Pangkah Ltd | E13: Integrated Chemical | F13: ZKI | H13: 48400000000 | K13: 44813 | L13: 44831 | M13: 44957 | N13: 44952 | Q13: 44978 | R13: - | S13: 44979 | U13: 44979 | W13: LOSS TECHNICAL | Y13: gagal lab test untuk PPD | Z13: 42895748682
A14: 10 | C14: 23110087-OR | D14: Premiere Oil Natuna Sea B.V | E14: Provision of Chemical Supply and Services | F14: ZKI | H14: 1124336 | K14: 45000 | L14: 45008 | N14: 45058 | Q14: 45077 | S14: 45077 | U14: 45082 | W14: LOSS TECHNICAL | Y14: Failed test report material compability test | Z14: 1116941.7
A15: 11 | C15: 1500000712 | D15: Star Energy (Kakap) Ltd | E15: Demulsifier & Reverse Demulsifier | F15: ZKI | K15: 45016 | L15: 45016 | W15: LOSS PQ ADMIN | Y15: tender diubah, harus melampirkan cure stetment untuk field trial
A16: 12 | C16: GA16021865A | D16: PEP Zona 10 - Tarakan | E16: Demulsifier, Deoiler | F16: ZKI | K16: 45072 | W16: LOSS PQ ADMIN | Y16: TKDN Expired
A17: 13 | C17: SA17018381A | D17: PEP - Sukowati | E17: Iron Catalyst | F17: ZKI | K17: 44958 | L17: 45208 | W17: LOSS PQ ADMIN | Y17: Spek pada sertifikat TKDN tidak sesuai dengan persyaratan tender
A18: 14 | C18: GA13020534A | D18: PEP Zona 7 - Subang | E18: Corrosion Inhibitor | F18: ZKI | K18: 45021 | L18: 45049 | N18: 45083 | Q18: 45100 | R18: 45100 | W18: LOSS PQ ADMIN | Y18: TKDN Expired
A19: 15 | C19: EPPC-230417A-P23 | D19: PEP Zona 9 - Tanjung | E19: Scale Inhibitor | F19: ZKI | K19: 45083 | L19: 45085 | W19: LOSS PQ ADMIN | Y19: TKDN Expired
A20: 16 | C20: CS43167 | D20: MEDCO E&P | E20: Jasa Demulsifier | F20: ZKI | K20: 45105 | L20: 45131 | W20: LOSS PQ ADMIN | Y20: Tidak punya BAP untuk Tender Servis
A21: 17 | C21: CM47919 | D21: Medco E&P Natuna | E21: Specialty Chemical | F21: ZKI | K21: 45180 | L21: 45205 | W21: LOSS PQ ADMIN | Y21: Tidak punya TKDN Scale Remover dan PO Pembelian 100 pcs Totetank/Copy kontrak
A22: 18 | C22: GA14016041A | D22: PHM | E22: Antifoam AFFF 3% | F22: ZKI | K22: 45083 | L22: 45132 | N22: 45111 | Q22: 45132 | W22: WITHDRAW | Y22: Tidak mempunyai produk yang harus disubmit dalam tender
A23: 19 | C23: NDS-10112312 | D23: ENI MUARA BAKAU B.V & ENI EAST SEPINGGAN LTD | E23: Commodity Chemicals | F23: ZKI | H23: 99396066242 | K23: 45091 | L23: 45098 | M23: 45195 | N23: 45195 | Q23: 45243 | S23: 45244 | W23: WITHDRAW | Y23: Tidak ada persiapan untuk submit sampel dan bid price
A24: 20 | C24: GZ0200664A | D24: PHR | E24: Surfaktan CEOR | F24: KONS. IFP | K24: 44931 | L24: 45148 | M24: 45239 | Y24: tidak lolos lab test, tahapan tender diperpanjang | AB24: =FALSE() -> FALSE | AC24: =FALSE() -> FALSE
A25: 21 | C25: GA13021998A | D25: PEP Zona 7 - Jatibarang | E25: Demulsifier | F25: ZKI | K25: 45077 | AB25: =FALSE() -> FALSE | AC25: =FALSE() -> FALSE | AD25: BELUM PQ
A26: 22 | C26: SA17023583A | D26: PHE WMO | E26: Integrated Chemical | F26: ZKI | I26: Dirahasiakan | K26: 45124 | L26: 45163 | M26: 45190 | N26: 45336 | Q26: 45231 | S26: 45351 | T26: 45281 | U26: 45351 | W26: WIN | X26: Berlanjut ke 2024-2025 | Y26: - Sudah proses lab test di Sucofindo, sudah selesai & lolos FT (pengumuman resmi dari panitia). - Telah dilakukan pembukaan sampul 1 dan menunggu informasi/undangan selanjutnya terkait pembukaan sampul 2 - Lolos evaluasi administrasi dan teknis (sampul 1), next pembukaan sampul 2 | AA26: ada totetank, menunggu field trial, head to head dengan LBU (totetank daily 4 pcs saja sisanya mau dinego dengan ibc plastik, basket butuh 22); douglas basket 3 pallet, paralel cek ke yang laing; MEA : invite meeting minggu depan; cari harga triazine impor sendiri, source lain di lokal, MEA & paraform dari luar | AB26: =FALSE() -> FALSE | AC26: =FALSE() -> FALSE
A27: 23 | C27: M23PL0028B | D27: Pertamina Drilling Services Indonesia | E27: LTC Chemical Aerated | F27: ZKI | K27: 45133 | S27: 45133 | U27: 45133 | W27: LOSS PRICE | Y27: klarifikasi 3 November 2023 | Z27: 896019360 | AB27: =FALSE() -> FALSE | AC27: =FALSE() -> FALSE | AD27: LOST
A28: 24 | C28: GA14024755A | D28: PHM | E28: Demulsifier Lapangan CPA | F28: ZKI | H28: 28237001760 | K28: 45149 | L28: 45163 | M28: 45190 | Q28: 45204 | X28: Berlanjut ke 2024-2025 | Y28: proses lab test di Lemigas | AA28: surfaktan petrogresik | AB28: =FALSE() -> FALSE | AC28: =FALSE() -> FALSE | AD28: follow up pendaftaran vendor
A29: 25 | C29: SA13025018A | D29: PEP Zona 7 - Tambun | E29: H2S Scavenger - Service | F29: ZKI | G29: 2409 | H29: 10388353000 | J29: 4312309.3 | K29: 45161 | L29: 45175 | M29: 45231 | N29: 45231 | U29: 45244 | W29: LOSS TECHNICAL | Y29: pembukaan sampul 1 terlebih dahulu, hasil per Tgl 22/12 dinyatakan tidak lulus, sanggahan sudah disampaikan, masih menunggu feedback dr pertamina, tanggal 5/01/2024 meeting klarifikasi bersama dengan pertamina | AB29: =FALSE() -> FALSE | AC29: =FALSE() -> FALSE | AD29: following PHE WMO
A30: 26 | C30: GA14025375A | D30: PHM | E30: Biocide Glutaraldehyde | F30: ZKI | H30: 44580848000 | K30: 45173 | L30: 45187 | M30: 45204 | Q30: 45251 | S30: 45385 | U30: 45385 | W30: LOSS PRICE | X30: Berlanjut ke 2024-2025 | Y30: - submit sample - telah dilakukan pembukaan dokumen penawaran | AB30: =FALSE() -> FALSE | AC30: =TRUE() -> TRUE | AD30: 23.12.27 : sudah minta target price
A31: 27 | C31: GA17024763A | D31: PEP Cepu | E31: Demulsifier | F31: ZKI | K31: 45176 | L31: 45209 | N31: 45289 | S31: 45299 | W31: WITHDRAW | X31: Berlanjut ke 2024-2025 | AB31: =FALSE() -> FALSE | AC31: =FALSE() -> FALSE | AD31: V:\SOURCING ZEKINDO\@ 000_TENDER\21. 23.12_Tender O&G_PEP Cepu
A32: 28 | C32: 1/PQ/9/2023 | D32: Chevron Makassar Limited - ENI | E32: Production Chemical Services Kalimantan Field | F32: ZKI | K32: 45184 | L32: 45226 | W32: CANCELED | Y32: Dibatalkan oleh pihak panitia | AB32: =FALSE() -> FALSE | AC32: =FALSE() -> FALSE
A33: 29 | C33: SA14025585A | D33: PHM | E33: North Area Production Liquid Treatment Service Contract | F33: ZKI | K33: 45184 | L33: 45211 | M33: 45236 | Q33: 45288 | S33: 45506 | U33: 45506 | W33: LOSS PRICE | X33: Berlanjut ke 2024-2025 | Y33: - pengambilan sampel liquid 17-20 Nov, bawa 6 tincan, sudah submit sample - Resampling PQ Teknis : Pengambilan sample di Handil II Base : 10 Maret 2024 Submit sample di Jakarta : 27 Maret 2024 - Telah dilakukan open-bid sampul 1 (Admin dan Teknis) | AB33: =FALSE() -> FALSE | AC33: =FALSE() -> FALSE | AD33: 23.12.28 belum ada formula dari R&D
A34: 30 | C34: SHUH-230592A-A10 | D34: PEP Zona 4 | E34: Demulsifier | F34: ZKI | K34: 45205 | L34: 45205 | AB34: =FALSE() -> FALSE | AC34: =FALSE() -> FALSE | AD34: BELUM PQ
A35: 31 | C35: SHUH-230631A-A10 | D35: PEP Zona 4 - Ramba | E35: Demulsifier & Deoiler | F35: ZKI | H35: 4952260000 | K35: 45216 | L35: 45216 | M35: 45244 | N35: 45236 | Q35: 45264 | R35: 45264 | S35: 45244 | U35: 45244 | X35: Berlanjut ke 2024-2025 | Y35: sampul 1 terlebih dahulu, pengambilan crude water 14/11, tahap klarifikasi/sanggahan atas hasil lab test | AB35: =FALSE() -> FALSE | AC35: =TRUE() -> TRUE | AD35: LOST?
A36: 32 | C36: SHUH-230634A-A10 | D36: PEP Zona 4 - Limau | E36: PPD | F36: ZKI | G36: 76000 | H36: 4940000000 | J36: 65000 | K36: 45216 | L36: 45216 | M36: 45233 | N36: 45233 | Q36: 45278 | R36: 45274 | S36: 45253 | U36: 45253 | W36: LOSS PRICE | X36: Berlanjut ke 2024-2025 | Y36: sampul 1 terlebih dahulu, pengambilan crude 6-8/11, pengujian sample di LEMIGAS, est. hasil mid januari, Lab test Lolos. Harga penawaran ranking 2 | AA36: submitted | AB36: =TRUE() -> TRUE | AC36: =TRUE() -> TRUE | AD36: SUBMIT
A37: 33 | C37: 23110515-OR (Re-Tender) | D37: Premier Oil Natuna Sea B.V. | E37: Provision of Chemical Supply and Services | F37: ZKI | I37: $ 966.188 (USD) | K37: 45251 | N37: 45252 | O37: 45268 | S37: 45301 | U37: 45302 | W37: LOSS TECHNICAL | X37: Berlanjut ke 2024-2025 | Y37: Sample chemical sudah ready, sudah submit sample dan dokumen penawaran, 26 januari 2024 technical clarification meeting | AA37: jadwal bid mundur | AB37: =TRUE() -> TRUE | AC37: =TRUE() -> TRUE | AD37: NOTIFY
A38: 34 | C38: NDS-10115464 | D38: ENI MUARA BAKAU B.V. | E38: Provision of Fluid Speciality Chemical Treatment Services | F38: ZKI | K38: 45252 | L38: 45261 | N38: 45357 | W38: WITHDRAW | X38: Berlanjut ke 2024-2025 | AB38: =FALSE() -> FALSE | AC38: =FALSE() -> FALSE
A39: 35 | C39: GA07028191A | D39: PHE Jambi Merang | E39: Purchase of Specialty Chemicals | F39: ZKI | I39: Dirahasiakan | N39: 45273 | O39: 45299 | S39: 45334 | U39: 45334 | W39: WIN | X39: Berlanjut ke 2024-2025 | Y39: - Jadwal pemasukan dokumen penawaran akan diinfo pada Pre-bid ke-2 stlh menunggu sample diterima oleh bidder - Lab Independen menggunakan LAPI ITB, tanggal submission sample menunggu sample water dr PHE JM diterima di KBI - Tahap Negosiasi Harga - Menang | AA39: jadwal bid mundur, sampel belum dapat | AB39: =FALSE() -> FALSE | AC39: =TRUE() -> TRUE
A40: 36 | C40: SA04027442A | D40: Pertamina Hulu Kalimantan Timur (PHKT) | E40: Penyediaan Jasa Bahan Kimia Produksi DOBU-DOBS | F40: ZKI | I40: Dirahasiakan | N40: 45279 | S40: 45358 | U40: 45358 | W40: WIN | X40: Berlanjut ke 2024-2025 | Y40: - Submit sample ke Lemigas : 7 Maret 2024 Submit sample ke PHKT : 19 Maret 2024 - Pembukaan Sampul 1 DOBS dan DOBU - Pembukaan sampul 2 DOBU | AB40: =FALSE() -> FALSE | AC40: =TRUE() -> TRUE | AD40: NOTIFY
...

Sheet 2022-2021
A1: MATRIKS TENDER ON PROGRESS ZEUS
A2: Periode 2021-2022 | sheet: 2022-2021
K3: Status (Tanggal Milestone) | AA3: Pembuatan PO Screening Test
A4: No | B4: Area | C4: Coll. No. Tender | D4: Customer | E4: Product | F4: Entitas/Konsorsium | G4: Qty (Liter/Barel) | H4: OE (Rp) | I4: OE Catatan | J4: IDR/L | K4: Regist | L4: PQ | M4: Technical PQ | N4: Prebid | O4: Second Prebid | P4: Technical Bidding | Q4: Sampel Chemical diterima di Lab Test | R4: Pengiriman Bukti Pembayaran Lab Independent | S4: Pemasukan Dokumen Penawaran | T4: Field Test | U4: Open Bid | V4: First Delivery | W4: Result | X4: Carry-over | Y4: Remarks | Z4: Nilai Proyek Fix/Nilai Penawaran Kita | AA4: Remark | AB4: P&L | AC4: Checklist Document | AD4: Catatan Internal
A5: 1 | C5: NDS-10098374 | D5: ENI | E5: Commodity Chemicals | F5: ZKI | H5: 90282792672 | K5: 44371 | L5: 44372 | N5: 44578 | P5: - | Q5: - | R5: - | S5: - | T5: - | U5: - | W5: WITHDRAW | X5: Lanjutan dari ALL | Y5: komoditi chemicals
A6: 2 | C6: SHUO-220224A-A17 | D6: EP Zona 11 - Sukowati Field | E6: Corrosion Inhibitor, Scale Inhibitor (Jasa) | F6: ZKI | G6: 75000 | H6: 9478208574 | J6: 126376.11 | K6: 44614 | L6: 44614 | N6: 44648 | P6: 44650 | Q6: 44673 | W6: WITHDRAW | Y6: mundur, ga ada untuk cek kinerja SI-CI
A7: 3 | C7: SHUH-211862A-A10 | D7: EP Zona 4 - Limau Field | E7: PPD | F7: ZKI | G7: 50000 | H7: 1700000000 | J7: 34000 | K7: 44593 | L7: 44593 | N7: 44648 | P7: 44656 | Q7: 44679 | S7: 44680 | W7: WITHDRAW | Y7: support Farca as existing
A8: 4 | C8: SHUH-210785A-A10 | D8: EP Zona 4 - Pendopo Field | E8: Demulsifier (Jasa) | F8: ZKI | G8: 3800 | H8: 12758851000 | J8: 3357592.4 | K8: 44602 | L8: 44602 | N8: 44656 | W8: WITHDRAW | Y8: biaya pengambilan sampel, labtest, dan FT terlalu tinggi
A9: 5 | C9: 22120122-DS | D9: Premiere Oil Natuna Sea BV | E9: Chemical Supply and Services | F9: Kons ZKI-TKT | K9: 44645 | L9: 44655 | W9: WITHDRAW | Y9: komoditi chemicals
A10: 6 | C10: SHUK-220248A-A13 | D10: EP Zona 7 - Tambun Field | E10: H2S Scavenger Performance Based | F10: ZKI | K10: 44624 | L10: 44624 | Q10: 44669 | R10: 44670 | W10: WITHDRAW | Y10: kumpulin sampel 18 Apr, Bayar ke Intertek 19 Apr
A11: 7 | C11: EPPC-220213A-P23 | D11: EP Zona 9 - Tanjung Field | E11: Scale Inhibitor | F11: ZKI | G11: 40000 | H11: 1270000000 | J11: 31750 | K11: 44616 | L11: 44616 | N11: 44648 | P11: 44658 | S11: 44691 | W11: WITHDRAW | Y11: tidak bisa mengikuti OE
A12: 8 | C12: SHUP-220382A-A19 | D12: EP Zona 13 - Donggi Matindok Field | E12: Antifoam | F12: ZKI | G12: 6400 | H12: 1318400000 | J12: 206000 | K12: 44648 | L12: 44648 | N12: 44677 | Q12: 44699 | S12: 44699 | W12: WITHDRAW | Y12: dukung Mits
A13: 9 | C13: CM22602 | D13: Medco E&P Indonesia | E13: Demul, PPD, SI | F13: ZKI | K13: 44663 | L13: 44706 | N13: 44664 | W13: WITHDRAW | Y13: karena tidak mendapatkan formula produk
A14: 10 | C14: PQM200206A-P26 | D14: EP Zona 4 - Sukowati Field | E14: Iron Catalyst (Fe) | F14: ZKI | K14: 44489 | L14: 44489 | N14: - | P14: - | Q14: - | R14: - | S14: - | T14: - | U14: - | W14: CANCELED | X14: Lanjutan dari ALL
A15: 11 | C15: SHUK-220039A-A13 | D15: EP Zona 7 - Tambun Field | E15: H2S Scavenger | F15: ZKI | K15: 44208 | L15: 44208 | N15: - | P15: - | Q15: - | R15: - | S15: - | T15: - | U15: - | W15: LOSS PQ ADMIN | Y15: surat pernyataan dibuat dengan hasil crop-an
A16: 12 | C16: SHUK-211229A-A13 | D16: EP Zona 7 - Subang Field | E16: PPD | F16: ZKI | K16: 44441 | L16: 44441 | N16: - | P16: 44459 | Q16: 44484 | R16: 44491 | S16: - | T16: - | U16: - | W16: LOSS TECHNICAL | X16: Lanjutan dari ALL | Y16: tidak lulus lab test di syslab
A17: 13 | C17: S373200010 | D17: PHE ONWJ | E17: Integrated Chemical Management Services | F17: Kons ZKI-TKT | G17: 730 | I17: dirahasiakan | K17: 44504 | L17: 44155 | N17: 44281 | P17: 44285 | Q17: 44545 | R17: - | S17: 44544 | T17: - | U17: 44544 | W17: LOSS TECHNICAL | X17: Lanjutan dari ALL | Y17: tidak lulus lab test untuk produk viscosity reducer
A18: 14 | C18: SHUH-211124A-A10 | D18: EP Zona 4 - Limau Field | E18: Scale Dispersant | F18: ZKI | G18: 50000 | H18: 2436250000 | J18: 48725 | K18: 44445 | L18: 44445 | N18: 44523 | P18: - | Q18: 44543 | R18: - | S18: 44543 | T18: - | U18: - | W18: LOSS TECHNICAL | X18: Lanjutan dari ALL | Y18: tidak lulus lab test intertek
A19: 15 | C19: SHUH-211605A-A10 | D19: EP Zona 4 - Prabumulih Field | E19: Scale Inhibitor (RETENDER) | F19: ZKI | G19: 118844 | H19: 4630814000 | J19: 38965.484 | K19: 44502 | L19: 44502 | N19: 44523 | P19: 44594 | Q19: 44547 | R19: 44554 | S19: 44551 | T19: 44627 | W19: LOSS TECHNICAL | X19: Lanjutan dari ALL | Y19: Field Test gagal di Field PBM untuk PRC Analisisnya
A20: 16 | C20: SHUK-220080A-A13 | D20: EP Zona 7 - Jatibarang Field | E20: PPD | F20: ZKI | G20: 687000 | H20: 24045000000 | J20: 35000 | K20: 44580 | L20: 44580 | N20: 44603 | P20: - | Q20: 44631 | R20: - | S20: 44631 | T20: - | W20: LOSS TECHNICAL | Y20: tidak lulus lab test, chemical settling dan gelling
A21: 17 | C21: SHUK-210979A-A13 | D21: EP Zona 7 - Jatibarang Field | E21: Demulsifier | F21: ZKI | G21: 40000 | H21: 1456000000 | J21: 36400 | K21: 44398 | L21: 44398 | N21: 44578 | P21: 44586 | Q21: 44441 | R21: - | S21: 44586 | T21: 44539 | U21: - | W21: LOSS PRICE | X21: Lanjutan dari ALL | Y21: kalah harga dari Cahaya
A22: 18 | C22: SHUH-211594A-A10 | D22: EP Zona 4 - Adera Field | E22: PPD | F22: ZKI | G22: 90000 | H22: 2857500000 | J22: 31750 | K22: 44504 | L22: 44504 | N22: 44524 | P22: 44530 | Q22: 44552 | R22: 44559 | S22: 44546 | T22: - | U22: 44602 | W22: LOSS PRICE | X22: Lanjutan dari ALL | Y22: kalah harga dari Cahaya, tapi yang menang LBU menang TKDN
A23: 19 | C23: SHUO-211272A-A17 | D23: EP Zona 11 - Sukowati Field | E23: H2S Scavenger | F23: ZKI | G23: 220000 | H23: 3630000000 | J23: 16500 | K23: 44536 | L23: 44536 | N23: 44586 | P23: - | Q23: 44603 | R23: - | S23: 44603 | T23: - | U23: 44630 | W23: LOSS PRICE | X23: Lanjutan dari ALL | Y23: kalah harga dari LBU
A24: 20 | C24: SHUK-M21PL0056A-A13 | D24: EP Zona 7 | E24: Scale Inhibitor | F24: ZKI | G24: 174724 | H24: 3415854200 | J24: 19550 | K24: 44512 | L24: 44512 | N24: 44558 | P24: 44578 | Q24: 44578 | R24: 44578 | S24: 44578 | U24: 44645 | W24: LOSS PRICE | Y24: kalah harga dari Mits Duta
A25: 21 | C25: SHUN-211051A-A16 | D25: EP Zona 10 - Sembakung Field | E25: Demulsifier | F25: ZKI | G25: 36000 | H25: 1944000000 | J25: 54000 | K25: 44412 | L25: 44412 | N25: 44455 | P25: 44510 | Q25: 44483 | R25: 44483 | S25: 44483 | T25: 44581 | U25: 44630 | W25: LOSS PRICE | X25: Lanjutan dari ALL | Y25: kalah harga dari Mits Duta
A26: 22 | C26: SHUK-211168A-A13 | D26: EP Zona 7 - Jatibarang Field | E26: H2S Scavenger | F26: ZKI | G26: 47000 | H26: 1480500000 | J26: 31500 | K26: 44421 | L26: 44421 | N26: 44440 | P26: - | Q26: 44497 | R26: - | S26: 44454 | T26: - | U26: 44546 | W26: WIN | X26: Lanjutan dari ALL | Y26: RO pertama 31 Jan 2022 | Z26: 1346550000
A27: 23 | C27: 21143M/OEKA/DM/XI/2021 | D27: PT Odira | E27: Demulsifier | F27: ZKI | K27: 44533 | L27: 44533 | X27: Lanjutan dari ALL | Y27: Menunggu Hasil PQ
A28: 24 | C28: SHUH-211800A-A10 | D28: EP Zona 4 - Prabumulih Field | E28: Bahan kimia Biocide, Corrosion Inhibitor, Scale Inhibitor, Oxygen Scavenger, Water Clarifier | F28: ZKI | K28: 44561 | L28: 44561 | Y28: Menunggu Hasil PQ
A29: 25 | C29: SHUK-221052A-A13 | D29: EP Zona 7 - Jatibarang Field | E29: Corrosion Inhibitor | F29: ZKI | G29: 210000 | H29: 4693500000 | J29: 22350 | K29: 44600 | L29: 44600 | N29: 44624 | Q29: 44655 | S29: 44655 | Y29: tunggu hasil lab test jatibarang | Z29: 3696000000
A30: 26 | C30: SHUH-220324-A10 | D30: EP Zona 4 - Limau Field | E30: Scale Dispersant | F30: ZKI | K30: 44636 | L30: 44636 | Y30: lulus PQ, menunggu dok. bidding
A31: 27 | C31: GZ0800142C-DSTNM | D31: PHM | E31: Corrosion Inhibitor | F31: ZKI | K31: 44636 | L31: 44655 | Y31: Menunggu Hasil PQ
A32: 28 | C32: EPPC-220363A-P23 | D32: EP Zona 9 - Tanjung Field | E32: PPD, Demulsifier, Deoiler | F32: ZKI | K32: 44648 | L32: 44648 | N32: 44694 | Y32: lulus PQ, menunggu dok. bidding
A33: 29 | C33: SHUN-220426A-A16 | D33: EP Zona 10 | E33: PPD | F33: ZKI | G33: 200000 | H33: 7800000000 | J33: 39000 | K33: 44657 | L33: 44657 | N33: 44677 | Q33: 44706 | S33: 44706 | Y33: sampel cap pos dikirimnya
C35: Legenda warna kolom Status
C36: Tanggal sudah lewat / milestone terlewati
C37: 7 sampai 14 hari menuju deadline (tender masih on going)
C38: Kurang dari 7 hari menuju deadline (tender masih on going)
C40: Result dikosongkan = tender masih ON GOING.

Sheet ALL
A1: MATRIKS TENDER ON PROGRESS ZEUS
A2: Periode 2020-2021 | sheet: ALL
K3: Status (Tanggal Milestone) | AA3: Pembuatan PO Screening Test
A4: No | B4: Area | C4: Coll. No. Tender | D4: Customer | E4: Product | F4: Entitas/Konsorsium | G4: Qty (Liter/Barel) | H4: OE (Rp) | I4: OE Catatan | J4: IDR/L | K4: Regist | L4: PQ | M4: Technical PQ | N4: Prebid | O4: Second Prebid | P4: Technical Bidding | Q4: Sampel Chemical diterima di Lab Test | R4: Pengiriman Bukti Pembayaran Lab Independent | S4: Pemasukan Dokumen Penawaran | T4: Field Test | U4: Open Bid | V4: First Delivery | W4: Result | X4: Carry-over | Y4: Remarks | Z4: Nilai Proyek Fix/Nilai Penawaran Kita | AA4: Remark | AB4: P&L | AC4: Checklist Document | AD4: Catatan Internal
A5: 1 | C5: PQPS000589-TAO | D5: PHM | E5: Drilling Waste Management Services | F5: TKT | K5: 44034 | L5: 44036 | W5: CANCELED | Y5: BATAL/BELUM ADA KEJELASAN HASIL PQ DARI TAHUN 2020
A6: 2 | C6: EPPA-201061A-P23 | D6: EP 5 | E6: RO Package | F6: TKT | K6: 44053 | L6: 44053 | W6: CANCELED
A7: 3 | C7: PQM200206A-P26 | D7: EP 4 - Sukowati Field | E7: Iron Catalyst (Fe) | F7: ZKI | K7: 44124 | L7: 44124 | W7: CANCELED | X7: Berlanjut ke 2022-2021
A8: 4 | C8: PR 7300002086 | D8: TPPI | E8: SPARING | F8: TKT | K8: 44147 | W8: CANCELED
A9: 5 | C9: SHUK-211195A-A13 | D9: Zona 7 - Balongan | E9: DUKUNGAN OPERASI IPAL | F9: TKT | K9: 44432 | L9: 44432 | W9: CANCELED
A10: 6 | C10: EP01-202120-P11 | D10: EP 5 - Tarakan Field | E10: WTP Waterflood SBK Tarakan Field | F10: TKT | G10: 3000 | H10: 25093250000 | K10: 44165 | L10: 44165 | N10: 44273 | U10: 44287 | W10: CANCELED | Y10: perubahan RKS
A11: 7 | C11: EPPA-210855A-P23 | D11: EP 5 - Samboja Field | E11: FASILITAS WATER TREATMENT | F11: TKT | H11: 24000000000 | K11: 44362 | L11: 44362 | N11: 44396 | U11: 44490 | W11: CANCELED | Y11: menunggu site visit
A12: 8 | C12: TBS. 001/004/SR/EPT-WTIP/II/2021 | D12: KSO EP-Techwin | E12: WTIP WATERFLOODING | F12: TKT | K12: 44427 | L12: 44431 | N12: 44482 | W12: CANCELED | Y12: menunggu site visit
A13: 9 | C13: EPMS-2102-B0A-P1H | D13: EP 3 - Subang Field | E13: PENYEDIAAN AIR BERSIH UNTUK KEBUTUHAN OPERASIONAL SUMUR | F13: Kons POCS-TKT | K13: 44260 | L13: 44260 | W13: CANCELED
A14: 10 | C14: EPP4-202190A-P3D | D14: PEP Tanjung Field | E14: Biocide | F14: ZKI | G14: 20000 | H14: 565800000 | J14: 28290 | K14: 44188 | L14: 44188 | N14: 44250 | U14: 44264 | W14: LOSS PRICE | Y14: KALAH HARGA dari Sasfindo
A15: 11 | C15: EPP4-202190A-P3D | D15: PEP Tanjung Field | E15: PPD, Demul, Deoiler | F15: ZKI | G15: 24400 | H15: 894305240 | J15: 36651.854 | K15: 44188 | L15: 44188 | N15: 44250 | U15: 44265 | W15: LOSS PRICE | Y15: KALAH HARGA dari EON
A16: 12 | C16: 093 | D16: PETRONAS Ketapang II LTD | E16: Integrated Chemical Supp & Service | F16: Kons ZKI-TKT | H16: 16301172000 | K16: 44054 | L16: 44056 | N16: 44153 | Q16: 44172 | U16: 44172 | W16: LOSS PRICE | Y16: KALAH HARGA dari LBU
A17: 13 | C17: EPM6-210284A-P28 | D17: EP 3 - Jatibarang Field | E17: SPARING (Retender) | F17: TKT | H17: 1810899700 | J17: 1653789.7 | K17: 44265 | L17: 44265 | N17: 44298 | U17: 44305 | W17: LOSS (PERLU DICEK) | Y17: gugur teknis, kesalahan input ijasah
A18: 14 | C18: PQPS000621-TIN | D18: PHM | E18: Demulsifier dan Deoiler | F18: Kons ZKI-TKT | H18: 33647800423 | K18: 44158 | L18: 44174 | N18: 44231 | U18: 44251 | W18: LOSS PRICE | Y18: KALAH HARGA dari HYDROCARBON
A19: 15 | C19: SHUH-210805A-A10 | D19: Zona 4 - Prabumulih Field | E19: Demulsifier | F19: ZKI | G19: 195400 | H19: 7928355000 | J19: 40575 | K19: 44354 | L19: 44354 | N19: 44403 | P19: 44413 | Q19: 44440 | U19: 44498 | W19: LOSS PRICE | Y19: KALAH HARGA dari EON
A20: 16 | C20: D261/RO#18780/QR#27649 | D20: Petrochina - Lagan | E20: Parafin Solvent - Pipeline | F20: TKT | G20: 2000 | H20: 35400000 | J20: 17700 | K20: 44524 | L20: 44524 | S20: 44525 | U20: 44525 | Y20: DIATAS OE
A21: 17 | C21: PQPM001111-TUW | D21: PHM | E21: Corrosion Inhibitor | F21: Kons ZKI-TKT | H21: 40800000000 | K21: 44186 | L21: 44204 | Q21: 44265 | W21: LOSS TECHNICAL | Y21: tidak lolos lab test, 3 kompetitor yang ikut FT (Eon, HEC, Elnusa)
A22: 18 | C22: S445200070 | D22: PHE WMO | E22: Chemical Supply & Services | F22: Kons ZKI-TKT | H22: 4504899.3 | K22: 44067 | L22: 44068 | N22: 44112 | P22: 44137 | Q22: 44148 | U22: 44148 | W22: LOSS TECHNICAL | Y22: tidak lolos lab test untuk produk Demul dan PPD, pemenang LBU
A23: 19 | C23: SHUH-2109071A-A10 | D23: Zona 4 - Prabumulih Field | E23: Scale Inhibitor | F23: ZKI | G23: 118844 | H23: 4630814000 | J23: 38965.484 | K23: 44389 | L23: 44389 | N23: 44433 | P23: 44438 | W23: LOSS TECHNICAL | Y23: tidak ada yang lulus lab test Intertek, Retender
A24: 20 | C24: SHUK-211011A-A13 | D24: Zona 7 - Subang Field | E24: Demulsifier | F24: ZKI | G24: 35285 | H24: 1234975000 | J24: 35000 | K24: 44399 | L24: 44399 | N24: 44435 | Q24: 44454 | T24: 44485 | U24: 44454 | W24: LOSS TECHNICAL | Y24: Tidak Lolos Field Test, yang lolos hanya Farca Risa
A25: 21 | C25: SHUK-211229A-A13 | D25: Zona 7 - Subang Field | E25: PPD | F25: ZKI | K25: 44441 | L25: 44441 | Q25: 44484 | W25: LOSS TECHNICAL | X25: Berlanjut ke 2022-2021 | Y25: tidak lulus bottle test syslab
A26: 22 | C26: SHUH-211511A-A10 | D26: Zona 4 - PHR Prabumulih Field | E26: Produced Water Treatment | F26: Kons ZKI-TKT | H26: 11560122061 | K26: 44488 | L26: 44488 | N26: 44523 | S26: 44530 | W26: LOSS TECHNICAL | Y26: miss surat penawaran teknis
A27: 23 | C27: 030093 | D27: EMCL | E27: Non Hazardous Waste & Sewage System | F27: TKT | H27: 6048734200 | K27: 44126 | L27: 44132 | N27: 44224 | U27: 44238 | W27: WITHDRAW | Y27: mengundurkan diri, SOW tidak termasuk dalam lingkup servis Triton
A28: 24 | C28: EPPA-202219A-P23 | D28: PEP Tanjung Field | E28: PPD, Demul, Deoiler (include Jasa) | F28: Kons ZKI-TKT | K28: 44202 | L28: 44202 | W28: WITHDRAW | Y28: mengundurkan diri, ketidakjelasan OE dan scoring untuk produk demul dan deoiler
A29: 25 | D29: EP 1 - Jambi Field | E29: Bottle Test & Field Test Chemical Treatment (Demulsifier, Deoiler, Scale Inhibitor) | F29: ZKI | N29: 44229 | W29: WITHDRAW | Y29: mengundurkan diri, karena free of charge untuk field trial
A30: 26 | C30: S5B1200170 | D30: PHE SIAK | E30: Jasa Perlakuan Minyak dan Air | F30: Kons ZKI-TKT | H30: 12932059500 | K30: 44047 | L30: 44049 | N30: 44200 | P30: 44216 | T30: 44339 | U30: 44256 | W30: WITHDRAW | Y30: mundur karena field trial FOC
A31: 27 | C31: BID 21-0057 | D31: Saka | E31: WWTP | F31: TKT | K31: 44298 | L31: 44306 | N31: 44476 | U31: 44490 | W31: WITHDRAW | Y31: tidak memenuhi persyaratan teknis (alat yang digunakan offshore)
A32: 28 | C32: SHUG-211303A-A07 | D32: Zona 1 - Rantau Field | E32: Scale Inhibitor | F32: ZKI | G32: 38400 | H32: 988800000 | J32: 25750 | K32: 44456 | L32: 44456 | N32: 44466 | P32: 44505 | Q32: 44525 | R32: 44525 | S32: 44525 | W32: WITHDRAW | Y32: mengundurkan diri
A33: 29 | C33: EP01-201787A-P11 | D33: EP 1 - Rantau Field | E33: WTP KSB Field Rantau (Retender) | F33: TKT | K33: 44097 | L33: 44097 | W33: RETENDER | Y33: RETENDER
A34: 30 | C34: EPM5-210059A-P27 | D34: EP 3 - Jatibarang Field | E34: PPD | F34: ZKI | K34: 44214 | L34: 44214 | W34: RETENDER | Y34: RETENDER
A35: 31 | C35: EPM6-210520A-P28 | D35: EP 3 - Subang Field | E35: Demulsifier | F35: ZKI | K35: 44298 | L35: 44298 | N35: 44326 | W35: RETENDER | Y35: RETENDER
A36: 32 | C36: EPKE-210302A-P3A | D36: EP 1 - Lirik Field | E36: Chemical Supply | F36: TKT | K36: 44271 | L36: 44271 | W36: LOSS PQ ADMIN | Y36: tidak lolos PQ bermasalah dengan penamaan yang berbeda untuk sertifikat TKDN
A37: 33 | C37: EPN4-210455A-P26 | D37: Zona 11 - Sukowati Field | E37: Chelating Agent | F37: ZKI | K37: 44344 | L37: 44344 | W37: LOSS PQ ADMIN | Y37: tidak lolos PQ karena tidak memiliki TKDN Chelating Agent
A38: 34 | C38: BID 21-0091 | D38: Saka | E38: EPCI For Produced Water Treatment | F38: TKT | K38: 44363 | L38: 44363 | W38: LOSS PQ ADMIN | Y38: tidak lolos PQ karena SIUJK tidak sesuai (kons. dnegan Profluid)
A39: 35 | C39: SHUK-2107B8A-A13 | D39: Zona 7 - Balongan | E39: PRECOMMISIONING, COMMISIONING, START-UP IPAL MOS BALONGAN | F39: TKT | K39: 44389 | L39: 44389 | W39: LOSS PQ ADMIN | Y39: tidak lolos PQ, sub bidang tidak sesuai
A40: 36 | C40: SHUH-210804A-A10 | D40: Zona 4 - Prabumulih Field | E40: Chemical Supply | F40: ZKI | K40: 44354 | L40: 44354 | W40: LOSS PQ ADMIN | Y40: email tidak masuk ukuran email terlalu besar, tetapi tidak ada penolakan dari email pertamina
...

Sheet Rekap
A1: REKAP HASIL TENDER
A2: Terhubung otomatis ke sheet periode. Angka ikut berubah saat data diperbarui.
A4: Kategori Hasil | B4: 2025-2026 | C4: 2024-2025 | D4: 2023-2024 | E4: 2021-2022 | F4: 2020-2021 | G4: TOTAL
A5: WIN | B5: =COUNTIF('2025-2026'!$W$5:$W$400,"WIN") -> 0 | C5: =COUNTIF('2024-2025'!$W$5:$W$400,"WIN") -> 9 | D5: =COUNTIF('2023-2024'!$W$5:$W$400,"WIN") -> 8 | E5: =COUNTIF('2022-2021'!$W$5:$W$400,"WIN") -> 1 | F5: =COUNTIF(ALL!$W$5:$W$400,"WIN") -> 6 | G5: =SUM(B5:F5) -> 24
A6: LOSS PRICE | B6: =COUNTIF('2025-2026'!$W$5:$W$400,"LOSS PRICE") -> 6 | C6: =COUNTIF('2024-2025'!$W$5:$W$400,"LOSS PRICE") -> 10 | D6: =COUNTIF('2023-2024'!$W$5:$W$400,"LOSS PRICE") -> 9 | E6: =COUNTIF('2022-2021'!$W$5:$W$400,"LOSS PRICE") -> 5 | F6: =COUNTIF(ALL!$W$5:$W$400,"LOSS PRICE") -> 5 | G6: =SUM(B6:F6) -> 35
A7: LOSS TECHNICAL | B7: =COUNTIF('2025-2026'!$W$5:$W$400,"LOSS TECHNICAL") -> 2 | C7: =COUNTIF('2024-2025'!$W$5:$W$400,"LOSS TECHNICAL") -> 10 | D7: =COUNTIF('2023-2024'!$W$5:$W$400,"LOSS TECHNICAL") -> 9 | E7: =COUNTIF('2022-2021'!$W$5:$W$400,"LOSS TECHNICAL") -> 5 | F7: =COUNTIF(ALL!$W$5:$W$400,"LOSS TECHNICAL") -> 7 | G7: =SUM(B7:F7) -> 33
A8: LOSS TECHNICAL (BOTTLE TEST) | B8: =COUNTIF('2025-2026'!$W$5:$W$400,"LOSS TECHNICAL (BOTTLE TEST)") -> 5 | C8: =COUNTIF('2024-2025'!$W$5:$W$400,"LOSS TECHNICAL (BOTTLE TEST)") -> 1 | D8: =COUNTIF('2023-2024'!$W$5:$W$400,"LOSS TECHNICAL (BOTTLE TEST)") -> 0 | E8: =COUNTIF('2022-2021'!$W$5:$W$400,"LOSS TECHNICAL (BOTTLE TEST)") -> 0 | F8: =COUNTIF(ALL!$W$5:$W$400,"LOSS TECHNICAL (BOTTLE TEST)") -> 0 | G8: =SUM(B8:F8) -> 6
A9: LOSS TECHNICAL (FIELD TRIAL) | B9: =COUNTIF('2025-2026'!$W$5:$W$400,"LOSS TECHNICAL (FIELD TRIAL)") -> 0 | C9: =COUNTIF('2024-2025'!$W$5:$W$400,"LOSS TECHNICAL (FIELD TRIAL)") -> 2 | D9: =COUNTIF('2023-2024'!$W$5:$W$400,"LOSS TECHNICAL (FIELD TRIAL)") -> 1 | E9: =COUNTIF('2022-2021'!$W$5:$W$400,"LOSS TECHNICAL (FIELD TRIAL)") -> 0 | F9: =COUNTIF(ALL!$W$5:$W$400,"LOSS TECHNICAL (FIELD TRIAL)") -> 0 | G9: =SUM(B9:F9) -> 3
A10: LOSS PQ ADMIN | B10: =COUNTIF('2025-2026'!$W$5:$W$400,"LOSS PQ ADMIN") -> 0 | C10: =COUNTIF('2024-2025'!$W$5:$W$400,"LOSS PQ ADMIN") -> 6 | D10: =COUNTIF('2023-2024'!$W$5:$W$400,"LOSS PQ ADMIN") -> 9 | E10: =COUNTIF('2022-2021'!$W$5:$W$400,"LOSS PQ ADMIN") -> 1 | F10: =COUNTIF(ALL!$W$5:$W$400,"LOSS PQ ADMIN") -> 5 | G10: =SUM(B10:F10) -> 21
A11: LOSS REGIST | B11: =COUNTIF('2025-2026'!$W$5:$W$400,"LOSS REGIST") -> 1 | C11: =COUNTIF('2024-2025'!$W$5:$W$400,"LOSS REGIST") -> 6 | D11: =COUNTIF('2023-2024'!$W$5:$W$400,"LOSS REGIST") -> 0 | E11: =COUNTIF('2022-2021'!$W$5:$W$400,"LOSS REGIST") -> 0 | F11: =COUNTIF(ALL!$W$5:$W$400,"LOSS REGIST") -> 0 | G11: =SUM(B11:F11) -> 7
A12: LOSS (PERLU DICEK) | B12: =COUNTIF('2025-2026'!$W$5:$W$400,"LOSS (PERLU DICEK)") -> 0 | C12: =COUNTIF('2024-2025'!$W$5:$W$400,"LOSS (PERLU DICEK)") -> 0 | D12: =COUNTIF('2023-2024'!$W$5:$W$400,"LOSS (PERLU DICEK)") -> 0 | E12: =COUNTIF('2022-2021'!$W$5:$W$400,"LOSS (PERLU DICEK)") -> 0 | F12: =COUNTIF(ALL!$W$5:$W$400,"LOSS (PERLU DICEK)") -> 1 | G12: =SUM(B12:F12) -> 1
A13: WITHDRAW | B13: =COUNTIF('2025-2026'!$W$5:$W$400,"WITHDRAW") -> 6 | C13: =COUNTIF('2024-2025'!$W$5:$W$400,"WITHDRAW") -> 9 | D13: =COUNTIF('2023-2024'!$W$5:$W$400,"WITHDRAW") -> 8 | E13: =COUNTIF('2022-2021'!$W$5:$W$400,"WITHDRAW") -> 9 | F13: =COUNTIF(ALL!$W$5:$W$400,"WITHDRAW") -> 6 | G13: =SUM(B13:F13) -> 38
A14: CANCELED | B14: =COUNTIF('2025-2026'!$W$5:$W$400,"CANCELED") -> 2 | C14: =COUNTIF('2024-2025'!$W$5:$W$400,"CANCELED") -> 6 | D14: =COUNTIF('2023-2024'!$W$5:$W$400,"CANCELED") -> 1 | E14: =COUNTIF('2022-2021'!$W$5:$W$400,"CANCELED") -> 1 | F14: =COUNTIF(ALL!$W$5:$W$400,"CANCELED") -> 10 | G14: =SUM(B14:F14) -> 20
A15: RETENDER | B15: =COUNTIF('2025-2026'!$W$5:$W$400,"RETENDER") -> 0 | C15: =COUNTIF('2024-2025'!$W$5:$W$400,"RETENDER") -> 0 | D15: =COUNTIF('2023-2024'!$W$5:$W$400,"RETENDER") -> 0 | E15: =COUNTIF('2022-2021'!$W$5:$W$400,"RETENDER") -> 0 | F15: =COUNTIF(ALL!$W$5:$W$400,"RETENDER") -> 3 | G15: =SUM(B15:F15) -> 3
A16: NO INFO | B16: =COUNTIF('2025-2026'!$W$5:$W$400,"NO INFO") -> 0 | C16: =COUNTIF('2024-2025'!$W$5:$W$400,"NO INFO") -> 1 | D16: =COUNTIF('2023-2024'!$W$5:$W$400,"NO INFO") -> 0 | E16: =COUNTIF('2022-2021'!$W$5:$W$400,"NO INFO") -> 0 | F16: =COUNTIF(ALL!$W$5:$W$400,"NO INFO") -> 0 | G16: =SUM(B16:F16) -> 1
A17: ON GOING (belum ada hasil) | B17: =SUMPRODUCT(--ISNUMBER('2025-2026'!$A$5:$A$400),--('2025-2026'!$W$5:$W$400="")) -> 15 | C17: =SUMPRODUCT(--ISNUMBER('2024-2025'!$A$5:$A$400),--('2024-2025'!$W$5:$W$400="")) -> 24 | D17: =SUMPRODUCT(--ISNUMBER('2023-2024'!$A$5:$A$400),--('2023-2024'!$W$5:$W$400="")) -> 11 | E17: =SUMPRODUCT(--ISNUMBER('2022-2021'!$A$5:$A$400),--('2022-2021'!$W$5:$W$400="")) -> 7 | F17: =SUMPRODUCT(--ISNUMBER(ALL!$A$5:$A$400),--(ALL!$W$5:$W$400="")) -> 28 | G17: =SUM(B17:F17) -> 85
